#VRML_SIM R2022b utf8

EXTERNPROTO "https://raw.githubusercontent.com/cyberbotics/webots/R2022b/projects/objects/backgrounds/protos/TexturedBackground.proto"
EXTERNPROTO "https://raw.githubusercontent.com/cyberbotics/webots/R2022b/projects/objects/backgrounds/protos/TexturedBackgroundLight.proto"

WorldInfo {
}
Viewpoint {
  orientation -0.07276258847746736 -0.8757653133365684 0.47722187887246 5.827369989180633
  position -0.6428917294913779 -0.04681365000473085 0.3110467375393837
}
TexturedBackground {
}
TexturedBackgroundLight {
}
Solid {
  children [
    Solid {
      children [
        Shape {
          appearance PBRAppearance {
            baseColorMap ImageTexture {
              url [
                "https://raw.githubusercontent.com/cyberbotics/webots/R2022b/projects/appearances/protos/textures/parquetry/chequered_parquetry_base_color.jpg"
              ]
            }
            roughness 1
            roughnessMap ImageTexture {
              url [
                "https://raw.githubusercontent.com/cyberbotics/webots/R2022b/projects/appearances/protos/textures/parquetry/chequered_parquetry_roughness.jpg"
              ]
            }
            metalness 0
            normalMap ImageTexture {
              url [
                "https://raw.githubusercontent.com/cyberbotics/webots/R2022b/projects/appearances/protos/textures/parquetry/chequered_parquetry_normal.jpg"
              ]
            }
            occlusionMap ImageTexture {
              url [
                "https://raw.githubusercontent.com/cyberbotics/webots/R2022b/projects/appearances/protos/textures/parquetry/chequered_parquetry_occlusion.jpg"
              ]
            }
          }
          geometry IndexedFaceSet {
            coord Coordinate {
              point [
                -0.5 -0.5 0
                0.5 -0.5 0
                -0.5 0.5 0
                0.5 0.5 0
              ]
            }
            texCoord TextureCoordinate {
              point [
                0 0
                2 0
                0 2
                2 2
              ]
            }
            coordIndex [
              2, 0, 1, 3, -1
            ]
            texCoordIndex [
              2, 0, 1, 3, -1
            ]
          }
        }
      ]
      name "floor"
      model "floor"
      boundingObject Plane {
      }
      locked TRUE
    }
    Solid {
      translation 0.505 0 0.05
      children [
        Shape {
          appearance PBRAppearance {
            baseColorMap ImageTexture {
              url [
                "https://raw.githubusercontent.com/cyberbotics/webots/R2022b/projects/appearances/protos/textures/brushed_aluminium/brushed_aluminium_base_color.jpg"
              ]
            }
            roughnessMap ImageTexture {
              url [
                "https://raw.githubusercontent.com/cyberbotics/webots/R2022b/projects/appearances/protos/textures/brushed_aluminium/brushed_aluminium_roughness.jpg"
              ]
            }
            normalMap ImageTexture {
              url [
                "https://raw.githubusercontent.com/cyberbotics/webots/R2022b/projects/appearances/protos/textures/brushed_aluminium/brushed_aluminium_normal.jpg"
              ]
            }
          }
          geometry IndexedFaceSet {
            coord Coordinate {
              point [
                -0.005 0.5 0.05
                0.005 0.5 0.05
                0.005 0.5 -0.05
                -0.005 0.5 -0.05
                -0.005 -0.5 -0.05
                0.005 -0.5 -0.05
                0.005 -0.5 0.05
                -0.005 -0.5 0.05
                -0.005 -0.5 0.05
                0.005 -0.5 0.05
                0.005 0.5 0.05
                -0.005 0.5 0.05
                0.005 -0.5 -0.05
                -0.005 -0.5 -0.05
                -0.005 0.5 -0.05
                0.005 0.5 -0.05
                -0.005 -0.5 -0.05
                -0.005 -0.5 0.05
                -0.005 0.5 0.05
                -0.005 0.5 -0.05
                0.005 -0.5 0.05
                0.005 -0.5 -0.05
                0.005 0.5 -0.05
                0.005 0.5 0.05
              ]
            }
            texCoord TextureCoordinate {
              point [
                0.01 0.1
                0 0.1
                0 0
                0.01 0
                0 0
                0.01 0
                0.01 0.1
                0 0.1
                0 0.01
                0 0
                1 0
                1 0.01
                0 0.01
                0 0
                1 0
                1 0.01
                1 0
                1 0.1
                0 0.1
                0 0
                0 0.1
                0 0
                1 0
                1 0.1
              ]
            }
            coordIndex [
              0, 1, 2, 3, -1, 4, 5, 6, 7, -1, 8, 9, 10, 11, -1, 12, 13, 14, 15, -1, 16, 17, 18, 19, -1, 20, 21, 22, 23, -1
            ]
            creaseAngle 1.5
          }
        }
      ]
      name "wall"
      model "box"
      boundingObject Box {
        size 0.01 1 0.1
      }
    }
    Solid {
      translation -0.505 0 0.05
      children [
        Shape {
          appearance PBRAppearance {
            baseColorMap ImageTexture {
              url [
                "https://raw.githubusercontent.com/cyberbotics/webots/R2022b/projects/appearances/protos/textures/brushed_aluminium/brushed_aluminium_base_color.jpg"
              ]
            }
            roughnessMap ImageTexture {
              url [
                "https://raw.githubusercontent.com/cyberbotics/webots/R2022b/projects/appearances/protos/textures/brushed_aluminium/brushed_aluminium_roughness.jpg"
              ]
            }
            normalMap ImageTexture {
              url [
                "https://raw.githubusercontent.com/cyberbotics/webots/R2022b/projects/appearances/protos/textures/brushed_aluminium/brushed_aluminium_normal.jpg"
              ]
            }
          }
          geometry IndexedFaceSet {
            coord Coordinate {
              point [
                -0.005 0.5 0.05
                0.005 0.5 0.05
                0.005 0.5 -0.05
                -0.005 0.5 -0.05
                -0.005 -0.5 -0.05
                0.005 -0.5 -0.05
                0.005 -0.5 0.05
                -0.005 -0.5 0.05
                -0.005 -0.5 0.05
                0.005 -0.5 0.05
                0.005 0.5 0.05
                -0.005 0.5 0.05
                0.005 -0.5 -0.05
                -0.005 -0.5 -0.05
                -0.005 0.5 -0.05
                0.005 0.5 -0.05
                -0.005 -0.5 -0.05
                -0.005 -0.5 0.05
                -0.005 0.5 0.05
                -0.005 0.5 -0.05
                0.005 -0.5 0.05
                0.005 -0.5 -0.05
                0.005 0.5 -0.05
                0.005 0.5 0.05
              ]
            }
            texCoord TextureCoordinate {
              point [
                0.01 0.1
                0 0.1
                0 0
                0.01 0
                0 0
                0.01 0
                0.01 0.1
                0 0.1
                0 0.01
                0 0
                1 0
                1 0.01
                0 0.01
                0 0
                1 0
                1 0.01
                1 0
                1 0.1
                0 0.1
                0 0
                0 0.1
                0 0
                1 0
                1 0.1
              ]
            }
            coordIndex [
              0, 1, 2, 3, -1, 4, 5, 6, 7, -1, 8, 9, 10, 11, -1, 12, 13, 14, 15, -1, 16, 17, 18, 19, -1, 20, 21, 22, 23, -1
            ]
            creaseAngle 1.5
          }
        }
      ]
      name "wall#2"
      model "box"
      boundingObject Box {
        size 0.01 1 0.1
      }
    }
    Solid {
      translation 0 0.505 0.05
      children [
        Shape {
          appearance PBRAppearance {
            baseColorMap ImageTexture {
              url [
                "https://raw.githubusercontent.com/cyberbotics/webots/R2022b/projects/appearances/protos/textures/brushed_aluminium/brushed_aluminium_base_color.jpg"
              ]
            }
            roughnessMap ImageTexture {
              url [
                "https://raw.githubusercontent.com/cyberbotics/webots/R2022b/projects/appearances/protos/textures/brushed_aluminium/brushed_aluminium_roughness.jpg"
              ]
            }
            normalMap ImageTexture {
              url [
                "https://raw.githubusercontent.com/cyberbotics/webots/R2022b/projects/appearances/protos/textures/brushed_aluminium/brushed_aluminium_normal.jpg"
              ]
            }
          }
          geometry IndexedFaceSet {
            coord Coordinate {
              point [
                -0.51 0.005 0.05
                0.51 0.005 0.05
                0.51 0.005 -0.05
                -0.51 0.005 -0.05
                -0.51 -0.005 -0.05
                0.51 -0.005 -0.05
                0.51 -0.005 0.05
                -0.51 -0.005 0.05
                -0.51 -0.005 0.05
                0.51 -0.005 0.05
                0.51 0.005 0.05
                -0.51 0.005 0.05
                0.51 -0.005 -0.05
                -0.51 -0.005 -0.05
                -0.51 0.005 -0.05
                0.51 0.005 -0.05
                -0.51 -0.005 -0.05
                -0.51 -0.005 0.05
                -0.51 0.005 0.05
                -0.51 0.005 -0.05
                0.51 -0.005 0.05
                0.51 -0.005 -0.05
                0.51 0.005 -0.05
                0.51 0.005 0.05
              ]
            }
            texCoord TextureCoordinate {
              point [
                1 0.09803921568627451
                0 0.09803921568627451
                0 0
                1 0
                0 0
                1 0
                1 0.09803921568627451
                0 0.09803921568627451
                0 1
                0 0
                0.00980392156862745 0
                0.00980392156862745 1
                0 1
                0 0
                0.00980392156862745 0
                0.00980392156862745 1
                0.00980392156862745 0
                0.00980392156862745 0.09803921568627451
                0 0.09803921568627451
                0 0
                0 0.09803921568627451
                0 0
                0.00980392156862745 0
                0.00980392156862745 0.09803921568627451
              ]
            }
            coordIndex [
              0, 1, 2, 3, -1, 4, 5, 6, 7, -1, 8, 9, 10, 11, -1, 12, 13, 14, 15, -1, 16, 17, 18, 19, -1, 20, 21, 22, 23, -1
            ]
            creaseAngle 1.5
          }
        }
      ]
      name "wall#3"
      model "box"
      boundingObject Box {
        size 1.02 0.01 0.1
      }
    }
    Solid {
      translation 0 -0.505 0.05
      children [
        Shape {
          appearance PBRAppearance {
            baseColorMap ImageTexture {
              url [
                "https://raw.githubusercontent.com/cyberbotics/webots/R2022b/projects/appearances/protos/textures/brushed_aluminium/brushed_aluminium_base_color.jpg"
              ]
            }
            roughnessMap ImageTexture {
              url [
                "https://raw.githubusercontent.com/cyberbotics/webots/R2022b/projects/appearances/protos/textures/brushed_aluminium/brushed_aluminium_roughness.jpg"
              ]
            }
            normalMap ImageTexture {
              url [
                "https://raw.githubusercontent.com/cyberbotics/webots/R2022b/projects/appearances/protos/textures/brushed_aluminium/brushed_aluminium_normal.jpg"
              ]
            }
          }
          geometry IndexedFaceSet {
            coord Coordinate {
              point [
                -0.51 0.005 0.05
                0.51 0.005 0.05
                0.51 0.005 -0.05
                -0.51 0.005 -0.05
                -0.51 -0.005 -0.05
                0.51 -0.005 -0.05
                0.51 -0.005 0.05
                -0.51 -0.005 0.05
                -0.51 -0.005 0.05
                0.51 -0.005 0.05
                0.51 0.005 0.05
                -0.51 0.005 0.05
                0.51 -0.005 -0.05
                -0.51 -0.005 -0.05
                -0.51 0.005 -0.05
                0.51 0.005 -0.05
                -0.51 -0.005 -0.05
                -0.51 -0.005 0.05
                -0.51 0.005 0.05
                -0.51 0.005 -0.05
                0.51 -0.005 0.05
                0.51 -0.005 -0.05
                0.51 0.005 -0.05
                0.51 0.005 0.05
              ]
            }
            texCoord TextureCoordinate {
              point [
                1 0.09803921568627451
                0 0.09803921568627451
                0 0
                1 0
                0 0
                1 0
                1 0.09803921568627451
                0 0.09803921568627451
                0 1
                0 0
                0.00980392156862745 0
                0.00980392156862745 1
                0 1
                0 0
                0.00980392156862745 0
                0.00980392156862745 1
                0.00980392156862745 0
                0.00980392156862745 0.09803921568627451
                0 0.09803921568627451
                0 0
                0 0.09803921568627451
                0 0
                0.00980392156862745 0
                0.00980392156862745 0.09803921568627451
              ]
            }
            coordIndex [
              0, 1, 2, 3, -1, 4, 5, 6, 7, -1, 8, 9, 10, 11, -1, 12, 13, 14, 15, -1, 16, 17, 18, 19, -1, 20, 21, 22, 23, -1
            ]
            creaseAngle 1.5
          }
        }
      ]
      name "wall#4"
      model "box"
      boundingObject Box {
        size 1.02 0.01 0.1
      }
    }
  ]
  name "rectangle arena"
  model "rectangle arena"
}
Robot {
  translation -0.06997708446634548 -0.08652774043714842 0.06070544856791225
  rotation 0.00890355256077906 0.02750589558955705 0.9995819888631517 2.4740652617905754
  children [
    BallJoint {
      jointParameters BallJointParameters {
        position 13.784438996629921
        anchor 0 0.03 -0.05
      }
      jointParameters2 JointParameters {
        position -1.7772548072009686
      }
      jointParameters3 JointParameters {
        position -49.415231874417316
        axis 0 1 0
      }
      endPoint Solid {
        translation -6.3696629025965235e-09 0.030000306946370375 -0.049994389521912055
        rotation -0.8230287196322398 -0.4198225026919272 0.38258697428689686 1.683099302018293
        children [
          DEF caster Shape {
            appearance Appearance {
              material Material {
                diffuseColor 0.239216 0.219608 0.27451
              }
            }
            geometry Sphere {
              radius 0.013
            }
          }
        ]
        name "solid(2)"
        boundingObject USE caster
        physics Physics {
        }
        linearVelocity -0.018579253891796713 -0.0235202393206513 -1.5428527723754121e-09
        angularVelocity 1.8092491783445837 -1.4291733762599215 0.08600707075534503
      }
    }
    Solid {
      translation 0 0.0515 0
      rotation 1 0 0 -1.5707953071795862
      children [
        DistanceSensor {
          rotation 0 1 0 -1.5707953071795862
          name "distance_sensor"
        }
        Shape {
          appearance Appearance {
            material Material {
              diffuseColor 0.239216 0.219608 0.27451
            }
          }
          geometry Cylinder {
            height 0.00645
            radius 0.004
          }
        }
      ]
      name "Distance Sensor 1"
    }
    Lidar {
      translation 0 0 0.05
      rotation 0 0 1 1.5708
      children [
        Solid {
          children [
            Shape {
              appearance Appearance {
                material Material {
                  diffuseColor 0.239216 0.219608 0.27451
                }
              }
              geometry Cylinder {
                height 0.0125
                radius 0.0125
              }
            }
          ]
        }
      ]
      numberOfLayers 1
    }
    DEF left_wheel_joint HingeJoint {
      jointParameters HingeJointParameters {
        position 134.6549928705608
        axis -1 0 0
        anchor -0.055 -0.02 -0.03
      }
      device [
        DEF left_wheel RotationalMotor {
          name "left_wheel"
        }
      ]
      endPoint Solid {
        translation -0.055 -0.02 -0.03
        rotation 0.6986863268517619 -0.15385462971594213 0.6986888932746556 3.4469067660102186
        children [
          DEF wheel_2 Shape {
            appearance Appearance {
              material Material {
                diffuseColor 0.239216 0.219608 0.27451
              }
            }
            geometry Cylinder {
              height 0.01
              radius 0.03
            }
          }
        ]
        name "solid(1)"
        boundingObject USE wheel_2
        physics Physics {
        }
        linearVelocity -0.018573478994138637 -0.02359139771520239 1.1246494398504552e-07
        angularVelocity 0.7863875558693249 -0.6191234454155892 0.0004683438732910809
      }
    }
    DEF right_wheel_joint HingeJoint {
      jointParameters HingeJointParameters {
        position 140.83098587107688
        axis -1 0 0
        anchor 0.0550001 -0.0198784 -0.0299555
      }
      device [
        DEF right_wheel RotationalMotor {
          name "right_wheel"
        }
      ]
      endPoint Solid {
        translation 0.0550001 -0.0197858604782916 -0.02988671390458835
        rotation -0.6939087787059744 0.19230062093003622 -0.6939099927402009 2.7616309111848674
        children [
          DEF wheel_1 Shape {
            appearance Appearance {
              material Material {
                diffuseColor 0.239216 0.219608 0.27451
              }
            }
            geometry Cylinder {
              height 0.01
              radius 0.03
            }
          }
        ]
        name "wheel_1"
        boundingObject USE wheel_1
        physics Physics {
        }
        linearVelocity -0.01857392341823192 -0.02359184985774773 -5.470583316473949e-08
        angularVelocity 0.7863875837955543 -0.619123466512625 0.00046834479955588476
      }
    }
    DEF chassi Solid {
      children [
        DEF body Shape {
          appearance Appearance {
            material Material {
              diffuseColor 0.207843 0.517647 0.894118
            }
          }
          geometry Box {
            size 0.1 0.1 0.1
          }
        }
      ]
    }
  ]
  boundingObject USE body
  physics Physics {
  }
  controller "amr"
  linearVelocity -0.018557252936929954 -0.023590402218696096 2.8140043913100998e-05
  angularVelocity 0.0011676036892263122 9.24013218465302e-05 -0.0006824589701778915
}
